Workbook
Name Slicer_Branch: #N/A
Name Slicer_Clean_City: #N/A
Name Slicer_Clean_payment_Method: #N/A
Name Slicer_Clean_Product_Name: #N/A

Sheet RAW DATA
A1: Transaction_ID | B1: Date | C1: Customer_ID | D1: Customer_Name | E1: Gender | F1: Age | G1: City | H1: Product_Category | I1: Product_Name | J1: Unit_Price | K1: Quantity | L1: Discount (%) | M1: Payment_Method | N1: Salesperson | O1: Branch | P1: Customer_Rating
A2: T100002 | B2: 2025-10-06 | C2: C9114 | D2: Peter | E2: Male | F2: 130 | G2: lagos | H2: Fashion | I2: Shirt | J2: 237.91 | K2: -2 | L2: -10 | M2: POS | N2: Dan | O2: North | P2: 4
A3: T100003 | B3: 2025-02-22 | C3: C7218 | D3: Peter | E3: Male | F3: 22 | G3: LAGOS | H3: Sports | I3: Ball | J3: 103.48 | K3: -2 | L3: 0 | N3: Dan | O3: West | P3: 4
A4: T100004 | B4: 2026-04-20 | C4: C9957 | D4: Aisha | E4: Male | F4: 55 | G4: PH | H4: Electronics | I4: Phone | J4: 436.14 | K4: -2 | L4: 10 | M4: POS | N4: Chi | O4: West
A5: T100005 | B5: 2026-02-21 | C5: C1077 | D5: James | E5: Female | F5: 130 | G5: Enugu | H5: Groceries | I5: Rice | J5: 430.25 | K5: -2 | L5: 10 | N5: Chi | O5: West | P5: 2
A6: T100006 | B6: 2025-10-13 | C6: C6441 | E6: Female | F6: 37 | G6: Lagos | H6: Home | I6: Chair | J6: 44.01 | K6: -2 | L6: 120 | M6: POS | N6: Dan | O6: West | P6: 4
A7: T100007 | B7: 10/11/2025 | C7: C6943 | D7: Aisha | E7: Female | F7: 130 | G7: Lagos | H7: Sports | I7: Ball | J7: 356.22 | K7: -2 | L7: 5 | M7: Mobile Money | N7: Chi | O7: West | P7: 1
A8: T100008 | B8: 2025-08-17 | C8: C1101 | D8: John | E8: Female | F8: 8 | G8: Enugu | H8: Electronics | I8: Phone | J8: 323.16 | K8: 4 | L8: 120 | M8: Transfer | N8: Chi | O8: South
A9: T100009 | B9: 2025-04-07 | C9: C8179 | D9: Mary | E9: Female | F9: 30 | G9: Abuja | H9: Sports | I9: Ball | J9: 126.25 | K9: 7 | L9: 0 | N9: Dan | O9: West | P9: 4
A10: T100010 | B10: 2025-04-01 | C10: C2862 | D10: Aisha | E10: Male | F10: 8 | G10: Abuja | H10: Sports | I10: Ball | J10: 233.45 | K10: 8 | L10: 10 | N10: Chi | O10: North | P10: 1
A11: T100011 | B11: 2025-09-10 | C11: C4724 | D11: Peter | E11: Female | F11: 8 | G11: PH | H11: Electronics | I11: Phone | J11: 150.57 | K11: -2 | L11: 10 | M11: Cash | N11: Chi | O11: West | P11: 4
A12: T100012 | B12: 2025-02-07 | C12: C2129 | D12: James | E12: Female | F12: 8 | G12: Lagos | H12: Fashion | I12: Shirt | J12: 49.62 | K12: 7 | L12: 120 | M12: Mobile Money | N12: Ada | O12: East | P12: 4
A13: T100013 | B13: 2025-06-09 | C13: C4291 | D13: Peter | E13: Male | F13: 130 | G13: Kano | H13: groceris | I13: Rice | J13: 409.19 | K13: -2 | L13: 120 | M13: POS | N13: Ada | O13: West | P13: 5
A14: T100014 | B14: 12/04/2025 | C14: C1596 | D14: John | E14: Male | F14: 130 | G14: Kano | H14: Home | I14: Chair | J14: 126.04 | K14: -2 | L14: 15 | M14: Transfer | N14: Ben | O14: South | P14: 4
A15: T100015 | B15: 2025-10-21 | C15: C1752 | D15: Aisha | E15: Female | F15: 130 | G15: Lagos | H15: Groceries | I15: Rice | J15: 477.09 | K15: -2 | L15: 0 | M15: Mobile Money | N15: Dan | O15: East | P15: 4
A16: T100016 | B16: 2025-05-25 | C16: C5577 | D16: Mary | E16: Male | F16: 130 | G16: Lagos | H16: groceris | I16: Rice | J16: 332 | K16: -2 | L16: 5 | M16: Transfer | N16: Dan | O16: East | P16: 4
A17: T100017 | B17: 2025-01-24 | C17: C8070 | D17: Grace | E17: Male | F17: 28 | G17: Lagos | H17: groceris | I17: Rice | J17: 484.12 | K17: 1 | L17: -10 | M17: POS | N17: Dan | O17: North | P17: 2
A18: T100018 | B18: 2026-02-22 | C18: C3714 | E18: Female | F18: 8 | G18: Kano | H18: groceris | I18: Rice | J18: 487.9 | K18: 6 | L18: -10 | M18: Transfer | N18: Ada | O18: South | P18: 2
A19: T100019 | B19: 2025-07-11 | C19: C4372 | D19: Peter | E19: Female | F19: 43 | G19: Abuja | H19: Sports | I19: Ball | J19: 398.62 | K19: -2 | L19: 10 | N19: Ben | O19: West | P19: 1
A20: T100020 | B20: 2026-02-25 | C20: C1826 | D20: Mary | E20: Male | F20: 130 | G20: Kano | H20: groceris | I20: Rice | J20: 68.67 | K20: 4 | L20: 10 | N20: Ben | O20: West
A21: T100021 | B21: 02/07/2025 | C21: C8532 | D21: John | E21: Male | F21: 8 | G21: Abuja | H21: Fashion | I21: Shirt | J21: 477.46 | K21: -2 | L21: -10 | M21: Cash | N21: Ada | O21: West | P21: 2
A22: T100022 | B22: 2025-10-19 | C22: C1462 | D22: David | E22: Male | F22: 130 | G22: Enugu | H22: Sports | I22: Ball | J22: 29.5 | K22: -2 | L22: 120 | M22: Cash | N22: Dan | O22: South | P22: 3
A23: T100023 | B23: 2025-08-16 | C23: C6481 | D23: James | E23: Male | F23: 8 | G23: lagos | H23: Beauty | I23: Cream | J23: 134.08 | K23: 5 | L23: 0 | N23: Ben | O23: South | P23: 2
A24: T100024 | B24: 2025-09-24 | C24: C2962 | D24: Grace | E24: Female | F24: 130 | G24: Abuja | H24: Fashion | I24: Shirt | J24: 388.4 | K24: -2 | L24: 15 | M24: Mobile Money | N24: Ada | O24: North | P24: 1
A25: T100025 | B25: 2025-06-10 | C25: C3575 | D25: James | E25: Female | F25: 130 | G25: Kano | H25: Fashion | I25: Shirt | J25: 279.11 | K25: -2 | L25: 10 | M25: Transfer | N25: Ben | O25: West
A26: T100026 | B26: 2025-05-26 | C26: C5211 | D26: David | E26: Male | F26: 130 | G26: Abuja | H26: Beauty | I26: Cream | J26: 205.37 | K26: -2 | L26: -10 | M26: Cash | N26: Ada | O26: North
A27: T100027 | B27: 2025-05-27 | C27: C5215 | D27: Aisha | E27: Female | F27: 58 | G27: PH | H27: groceris | I27: Rice | J27: 72.55 | K27: 6 | L27: 15 | M27: Mobile Money | N27: Ben | O27: East | P27: 1
A28: T100028 | B28: 07/01/2025 | C28: C8821 | D28: Mary | E28: Female | F28: 130 | G28: lagos | H28: groceris | I28: Rice | J28: 275.95 | K28: -2 | L28: 10 | N28: Dan | O28: West | P28: 3
A29: T100029 | B29: 2025-10-19 | C29: C2182 | D29: Aisha | E29: Female | F29: 8 | G29: Enugu | H29: Beauty | I29: Cream | J29: 161.33 | K29: 4 | L29: 10 | M29: Cash | N29: Ben | O29: East | P29: 3
A30: T100030 | B30: 2026-01-06 | C30: C5052 | E30: Female | F30: 58 | G30: Lagos | H30: Beauty | I30: Cream | J30: 416.14 | K30: 10 | L30: 120 | M30: Mobile Money | N30: Ada | O30: North | P30: 1
A31: T100031 | B31: 2026-02-16 | C31: C6457 | D31: John | E31: Male | F31: 8 | G31: PH | H31: groceris | I31: Rice | J31: 258.57 | K31: 2 | L31: -10 | M31: POS | N31: Ben | O31: West | P31: 3
A32: T100032 | B32: 2025-03-23 | C32: C8802 | D32: John | E32: Male | F32: 130 | G32: LAGOS | H32: Sports | I32: Ball | J32: 395.37 | K32: -2 | L32: 5 | M32: Mobile Money | N32: Ada | O32: South | P32: 4
A33: T100033 | B33: 2025-10-09 | C33: C7652 | D33: Aisha | E33: Male | F33: 37 | G33: Kano | H33: Sports | I33: Ball | J33: 429.08 | K33: 9 | L33: 0 | M33: Mobile Money | N33: Chi | O33: East | P33: 4
A34: T100034 | B34: 2025-07-11 | C34: C9293 | D34: David | E34: Female | F34: 35 | G34: Enugu | H34: groceris | I34: Rice | J34: 467.61 | K34: -2 | L34: 120 | M34: Transfer | N34: Chi | O34: East | P34: 4
A35: T100035 | B35: 13/03/2026 | C35: C2683 | D35: Mary | E35: Female | F35: 130 | G35: PH | H35: Beauty | I35: Cream | J35: 402.37 | K35: 10 | L35: 0 | M35: Transfer | N35: Dan | O35: South | P35: 4
A36: T100036 | B36: 2025-12-30 | C36: C1794 | D36: Grace | E36: Male | F36: 19 | G36: LAGOS | H36: Home | I36: Chair | J36: 489.41 | K36: 1 | L36: 0 | M36: Transfer | N36: Chi | O36: South | P36: 3
A37: T100037 | B37: 2025-11-16 | C37: C3074 | D37: John | E37: Female | F37: 64 | G37: LAGOS | H37: Fashion | I37: Shirt | J37: 203.77 | K37: 9 | L37: 120 | M37: Transfer | N37: Chi | O37: South | P37: 3
A38: T100038 | B38: 2025-07-10 | C38: C2121 | D38: James | E38: Female | F38: 8 | G38: PH | H38: Sports | I38: Ball | J38: 333.17 | K38: 8 | L38: -10 | M38: Cash | N38: Ada | O38: South | P38: 4
A39: T100039 | B39: 2025-12-11 | C39: C5675 | D39: John | E39: Female | F39: 130 | G39: Kano | H39: Home | I39: Chair | J39: 166.86 | K39: -2 | L39: 5 | M39: Mobile Money | N39: Chi | O39: South | P39: 3
A40: T100040 | B40: 2025-01-28 | C40: C5040 | D40: John | E40: Female | F40: 19 | G40: Kano | H40: Beauty | I40: Cream | J40: 442.23 | K40: -2 | L40: 120 | M40: POS | N40: Chi | O40: South | P40: 1
...

Sheet Pivot Tables
B3: Row Labels | C3: Sum of Total_sales
B4: Electronics | C4: 58846.282
B5: Fashion | C5: 40216.066
B6: Grand Total | C6: 99062.348
B15: Row Labels | C15: Sum of Total_sales
B16: Ada | C16: 232281.62
B17: Ben | C17: 172623.49
B18: Chi | C18: 171840.88
B19: Dan | C19: 189322.94
B20: (blank)
B21: Grand Total | C21: 766068.92
B25: Row Labels | C25: Sum of Total_sales
B26: East | C26: 192925.66
B27: North | C27: 209640.86
B28: South | C28: 168416.76
B29: West | C29: 195085.64
B30: (blank)
B31: Grand Total | C31: 766068.92
B36: Row Labels | C36: Sum of Total_sales
B37: Abuja | C37: 138012.53
B38: Enugu | C38: 107638.82
B39: Kano | C39: 107389.43
B40: Lagos | C40: 308160.4
B41: Ph | C41: 104867.74
B42: (blank)
B43: Grand Total | C43: 766068.92
B48: Row Labels | C48: Sum of Total_sales
C49: 165592.05
B50: Cash | C50: 163846.56
B51: Mobile Money | C51: 139579.29
B52: Pos | C52: 142010.37
B53: Transfer | C53: 155040.65
B54: Grand Total | C54: 766068.92

Sheet WORKING DATA
A1: Transaction_ID | B1: Date | C1: Customer_ID | D1: Customer_Name | E1: Clean_Customers_Name | F1: Gender | G1: Age | H1: Clean_Age | I1: City | J1: Clean_City | K1: Product_Category | L1: Clean_Product_Name | M1: Product_Name | N1: Clean_Unit_Price | O1: Unit_Price | P1: Quantity | Q1: Clean_Quantity | R1: Discount (%) | S1: Clean_Discount | T1: Payment_Method | U1: Clean_payment_Method | V1: Salesperson | W1: Clean_salesperson | X1: Branch | Y1: Customer_Rating | Z1: Missing Data check | AA1: Total_sales
A2: T100002 | B2: 2025-10-06 | C2: C9114 | D2: Peter | E2: =PROPER(TRIM(D2)) -> Peter | F2: Male | G2: 130 | H2: =IF(AND(G2>18, G2<65), "Valid", "Invalid") -> Invalid | I2: lagos | J2: =PROPER(TRIM(I2)) -> Lagos | K2: Fashion | L2: =PROPER(TRIM(K2)) -> Fashion | M2: Shirt | N2: =PROPER(TRIM(M2)) -> Shirt | O2: 237.91 | P2: -2 | Q2: =IF(P2<1, 1, P2) -> 1 | R2: -10 | S2: =IF(OR(R2<0,R2>100),"invalid","Valid") -> invalid | T2: POS | U2: =PROPER(TRIM(T2)) -> Pos | V2: Dan | W2: =PROPER(TRIM(V2)) -> Dan | X2: North | Y2: 4 | Z2: =IF(D2="", "Missing", "ok") -> ok | AA2: =(O2*Q2)*(1-R2/100) -> 261.701
A3: T100003 | B3: 2025-02-22 | C3: C7218 | D3: Peter | E3: =PROPER(TRIM(D3)) -> Peter | F3: Male | G3: 22 | H3: =IF(AND(G3>18, G3<65), "Valid", "Invalid") -> Valid | I3: LAGOS | J3: =PROPER(TRIM(I3)) -> Lagos | K3: Sports | L3: =PROPER(TRIM(K3)) -> Sports | M3: Ball | N3: =PROPER(TRIM(M3)) -> Ball | O3: 103.48 | P3: -2 | Q3: =IF(P3<1, 1, P3) -> 1 | R3: 0 | S3: =IF(OR(R3<0,R3>100),"invalid","Valid") -> Valid | U3: =PROPER(TRIM(T3)) | V3: Dan | W3: =PROPER(TRIM(V3)) -> Dan | X3: West | Y3: 4 | Z3: =IF(D3="", "Missing", "ok") -> ok | AA3: =(O3*Q3)*(1-R3/100) -> 103.48
A4: T100004 | B4: 2026-04-20 | C4: C9957 | D4: Aisha | E4: =PROPER(TRIM(D4)) -> Aisha | F4: Male | G4: 55 | H4: =IF(AND(G4>18, G4<65), "Valid", "Invalid") -> Valid | I4: PH | J4: =PROPER(TRIM(I4)) -> Ph | K4: Electronics | L4: =PROPER(TRIM(K4)) -> Electronics | M4: Phone | N4: =PROPER(TRIM(M4)) -> Phone | O4: 436.14 | P4: -2 | Q4: =IF(P4<1, 1, P4) -> 1 | R4: 10 | S4: =IF(OR(R4<0,R4>100),"invalid","Valid") -> Valid | T4: POS | U4: =PROPER(TRIM(T4)) -> Pos | V4: Chi | W4: =PROPER(TRIM(V4)) -> Chi | X4: West | Z4: =IF(D4="", "Missing", "ok") -> ok | AA4: =(O4*Q4)*(1-R4/100) -> 392.526
A5: T100005 | B5: 2026-02-21 | C5: C1077 | D5: James | E5: =PROPER(TRIM(D5)) -> James | F5: Female | G5: 130 | H5: =IF(AND(G5>18, G5<65), "Valid", "Invalid") -> Invalid | I5: Enugu | J5: =PROPER(TRIM(I5)) -> Enugu | K5: Groceries | L5: =PROPER(TRIM(K5)) -> Groceries | M5: Rice | N5: =PROPER(TRIM(M5)) -> Rice | O5: 430.25 | P5: -2 | Q5: =IF(P5<1, 1, P5) -> 1 | R5: 10 | S5: =IF(OR(R5<0,R5>100),"invalid","Valid") -> Valid | U5: =PROPER(TRIM(T5)) | V5: Chi | W5: =PROPER(TRIM(V5)) -> Chi | X5: West | Y5: 2 | Z5: =IF(D5="", "Missing", "ok") -> ok | AA5: =(O5*Q5)*(1-R5/100) -> 387.225
A6: T100006 | B6: 2025-10-13 | C6: C6441 | E6: =PROPER(TRIM(D6)) | F6: Female | G6: 37 | H6: =IF(AND(G6>18, G6<65), "Valid", "Invalid") -> Valid | I6: Lagos | J6: =PROPER(TRIM(I6)) -> Lagos | K6: Home | L6: =PROPER(TRIM(K6)) -> Home | M6: Chair | N6: =PROPER(TRIM(M6)) -> Chair | O6: 44.01 | P6: -2 | Q6: =IF(P6<1, 1, P6) -> 1 | R6: 120 | S6: =IF(OR(R6<0,R6>100),"invalid","Valid") -> invalid | T6: POS | U6: =PROPER(TRIM(T6)) -> Pos | V6: Dan | W6: =PROPER(TRIM(V6)) -> Dan | X6: West | Y6: 4 | Z6: =IF(D6="", "Missing", "ok") -> Missing | AA6: =(O6*Q6)*(1-R6/100) -> -8.802
A7: T100007 | B7: 10/11/2025 | C7: C6943 | D7: Aisha | E7: =PROPER(TRIM(D7)) -> Aisha | F7: Female | G7: 130 | H7: =IF(AND(G7>18, G7<65), "Valid", "Invalid") -> Invalid | I7: Lagos | J7: =PROPER(TRIM(I7)) -> Lagos | K7: Sports | L7: =PROPER(TRIM(K7)) -> Sports | M7: Ball | N7: =PROPER(TRIM(M7)) -> Ball | O7: 356.22 | P7: -2 | Q7: =IF(P7<1, 1, P7) -> 1 | R7: 5 | S7: =IF(OR(R7<0,R7>100),"invalid","Valid") -> Valid | T7: Mobile Money | U7: =PROPER(TRIM(T7)) -> Mobile Money | V7: Chi | W7: =PROPER(TRIM(V7)) -> Chi | X7: West | Y7: 1 | Z7: =IF(D7="", "Missing", "ok") -> ok | AA7: =(O7*Q7)*(1-R7/100) -> 338.409
A8: T100008 | B8: 2025-08-17 | C8: C1101 | D8: John | E8: =PROPER(TRIM(D8)) -> John | F8: Female | G8: 8 | H8: =IF(AND(G8>18, G8<65), "Valid", "Invalid") -> Invalid | I8: Enugu | J8: =PROPER(TRIM(I8)) -> Enugu | K8: Electronics | L8: =PROPER(TRIM(K8)) -> Electronics | M8: Phone | N8: =PROPER(TRIM(M8)) -> Phone | O8: 323.16 | P8: 4 | Q8: =IF(P8<1, 1, P8) -> 4 | R8: 120 | S8: =IF(OR(R8<0,R8>100),"invalid","Valid") -> invalid | T8: Transfer | U8: =PROPER(TRIM(T8)) -> Transfer | V8: Chi | W8: =PROPER(TRIM(V8)) -> Chi | X8: South | Z8: =IF(D8="", "Missing", "ok") -> ok | AA8: =(O8*Q8)*(1-R8/100) -> -258.528
A9: T100009 | B9: 2025-04-07 | C9: C8179 | D9: Mary | E9: =PROPER(TRIM(D9)) -> Mary | F9: Female | G9: 30 | H9: =IF(AND(G9>18, G9<65), "Valid", "Invalid") -> Valid | I9: Abuja | J9: =PROPER(TRIM(I9)) -> Abuja | K9: Sports | L9: =PROPER(TRIM(K9)) -> Sports | M9: Ball | N9: =PROPER(TRIM(M9)) -> Ball | O9: 126.25 | P9: 7 | Q9: =IF(P9<1, 1, P9) -> 7 | R9: 0 | S9: =IF(OR(R9<0,R9>100),"invalid","Valid") -> Valid | U9: =PROPER(TRIM(T9)) | V9: Dan | W9: =PROPER(TRIM(V9)) -> Dan | X9: West | Y9: 4 | Z9: =IF(D9="", "Missing", "ok") -> ok | AA9: =(O9*Q9)*(1-R9/100) -> 883.75
A10: T100010 | B10: 2025-04-01 | C10: C2862 | D10: Aisha | E10: =PROPER(TRIM(D10)) -> Aisha | F10: Male | G10: 8 | H10: =IF(AND(G10>18, G10<65), "Valid", "Invalid") -> Invalid | I10: Abuja | J10: =PROPER(TRIM(I10)) -> Abuja | K10: Sports | L10: =PROPER(TRIM(K10)) -> Sports | M10: Ball | N10: =PROPER(TRIM(M10)) -> Ball | O10: 233.45 | P10: 8 | Q10: =IF(P10<1, 1, P10) -> 8 | R10: 10 | S10: =IF(OR(R10<0,R10>100),"invalid","Valid") -> Valid | U10: =PROPER(TRIM(T10)) | V10: Chi | W10: =PROPER(TRIM(V10)) -> Chi | X10: North | Y10: 1 | Z10: =IF(D10="", "Missing", "ok") -> ok | AA10: =(O10*Q10)*(1-R10/100) -> 1680.84
A11: T100011 | B11: 2025-09-10 | C11: C4724 | D11: Peter | E11: =PROPER(TRIM(D11)) -> Peter | F11: Female | G11: 8 | H11: =IF(AND(G11>18, G11<65), "Valid", "Invalid") -> Invalid | I11: PH | J11: =PROPER(TRIM(I11)) -> Ph | K11: Electronics | L11: =PROPER(TRIM(K11)) -> Electronics | M11: Phone | N11: =PROPER(TRIM(M11)) -> Phone | O11: 150.57 | P11: -2 | Q11: =IF(P11<1, 1, P11) -> 1 | R11: 10 | S11: =IF(OR(R11<0,R11>100),"invalid","Valid") -> Valid | T11: Cash | U11: =PROPER(TRIM(T11)) -> Cash | V11: Chi | W11: =PROPER(TRIM(V11)) -> Chi | X11: West | Y11: 4 | Z11: =IF(D11="", "Missing", "ok") -> ok | AA11: =(O11*Q11)*(1-R11/100) -> 135.513
A12: T100012 | B12: 2025-02-07 | C12: C2129 | D12: James | E12: =PROPER(TRIM(D12)) -> James | F12: Female | G12: 8 | H12: =IF(AND(G12>18, G12<65), "Valid", "Invalid") -> Invalid | I12: Lagos | J12: =PROPER(TRIM(I12)) -> Lagos | K12: Fashion | L12: =PROPER(TRIM(K12)) -> Fashion | M12: Shirt | N12: =PROPER(TRIM(M12)) -> Shirt | O12: 49.62 | P12: 7 | Q12: =IF(P12<1, 1, P12) -> 7 | R12: 120 | S12: =IF(OR(R12<0,R12>100),"invalid","Valid") -> invalid | T12: Mobile Money | U12: =PROPER(TRIM(T12)) -> Mobile Money | V12: Ada | W12: =PROPER(TRIM(V12)) -> Ada | X12: East | Y12: 4 | Z12: =IF(D12="", "Missing", "ok") -> ok | AA12: =(O12*Q12)*(1-R12/100) -> -69.468
A13: T100013 | B13: 2025-06-09 | C13: C4291 | D13: Peter | E13: =PROPER(TRIM(D13)) -> Peter | F13: Male | G13: 130 | H13: =IF(AND(G13>18, G13<65), "Valid", "Invalid") -> Invalid | I13: Kano | J13: =PROPER(TRIM(I13)) -> Kano | K13: groceris | L13: =PROPER(TRIM(K13)) -> Groceris | M13: Rice | N13: =PROPER(TRIM(M13)) -> Rice | O13: 409.19 | P13: -2 | Q13: =IF(P13<1, 1, P13) -> 1 | R13: 120 | S13: =IF(OR(R13<0,R13>100),"invalid","Valid") -> invalid | T13: POS | U13: =PROPER(TRIM(T13)) -> Pos | V13: Ada | W13: =PROPER(TRIM(V13)) -> Ada | X13: West | Y13: 5 | Z13: =IF(D13="", "Missing", "ok") -> ok | AA13: =(O13*Q13)*(1-R13/100) -> -81.838
A14: T100014 | B14: 12/04/2025 | C14: C1596 | D14: John | E14: =PROPER(TRIM(D14)) -> John | F14: Male | G14: 130 | H14: =IF(AND(G14>18, G14<65), "Valid", "Invalid") -> Invalid | I14: Kano | J14: =PROPER(TRIM(I14)) -> Kano | K14: Home | L14: =PROPER(TRIM(K14)) -> Home | M14: Chair | N14: =PROPER(TRIM(M14)) -> Chair | O14: 126.04 | P14: -2 | Q14: =IF(P14<1, 1, P14) -> 1 | R14: 15 | S14: =IF(OR(R14<0,R14>100),"invalid","Valid") -> Valid | T14: Transfer | U14: =PROPER(TRIM(T14)) -> Transfer | V14: Ben | W14: =PROPER(TRIM(V14)) -> Ben | X14: South | Y14: 4 | Z14: =IF(D14="", "Missing", "ok") -> ok | AA14: =(O14*Q14)*(1-R14/100) -> 107.134
A15: T100015 | B15: 2025-10-21 | C15: C1752 | D15: Aisha | E15: =PROPER(TRIM(D15)) -> Aisha | F15: Female | G15: 130 | H15: =IF(AND(G15>18, G15<65), "Valid", "Invalid") -> Invalid | I15: Lagos | J15: =PROPER(TRIM(I15)) -> Lagos | K15: Groceries | L15: =PROPER(TRIM(K15)) -> Groceries | M15: Rice | N15: =PROPER(TRIM(M15)) -> Rice | O15: 477.09 | P15: -2 | Q15: =IF(P15<1, 1, P15) -> 1 | R15: 0 | S15: =IF(OR(R15<0,R15>100),"invalid","Valid") -> Valid | T15: Mobile Money | U15: =PROPER(TRIM(T15)) -> Mobile Money | V15: Dan | W15: =PROPER(TRIM(V15)) -> Dan | X15: East | Y15: 4 | Z15: =IF(D15="", "Missing", "ok") -> ok | AA15: =(O15*Q15)*(1-R15/100) -> 477.09
A16: T100016 | B16: 2025-05-25 | C16: C5577 | D16: Mary | E16: =PROPER(TRIM(D16)) -> Mary | F16: Male | G16: 130 | H16: =IF(AND(G16>18, G16<65), "Valid", "Invalid") -> Invalid | I16: Lagos | J16: =PROPER(TRIM(I16)) -> Lagos | K16: groceris | L16: =PROPER(TRIM(K16)) -> Groceris | M16: Rice | N16: =PROPER(TRIM(M16)) -> Rice | O16: 332 | P16: -2 | Q16: =IF(P16<1, 1, P16) -> 1 | R16: 5 | S16: =IF(OR(R16<0,R16>100),"invalid","Valid") -> Valid | T16: Transfer | U16: =PROPER(TRIM(T16)) -> Transfer | V16: Dan | W16: =PROPER(TRIM(V16)) -> Dan | X16: East | Y16: 4 | Z16: =IF(D16="", "Missing", "ok") -> ok | AA16: =(O16*Q16)*(1-R16/100) -> 315.4
A17: T100017 | B17: 2025-01-24 | C17: C8070 | D17: Grace | E17: =PROPER(TRIM(D17)) -> Grace | F17: Male | G17: 28 | H17: =IF(AND(G17>18, G17<65), "Valid", "Invalid") -> Valid | I17: Lagos | J17: =PROPER(TRIM(I17)) -> Lagos | K17: groceris | L17: =PROPER(TRIM(K17)) -> Groceris | M17: Rice | N17: =PROPER(TRIM(M17)) -> Rice | O17: 484.12 | P17: 1 | Q17: =IF(P17<1, 1, P17) -> 1 | R17: -10 | S17: =IF(OR(R17<0,R17>100),"invalid","Valid") -> invalid | T17: POS | U17: =PROPER(TRIM(T17)) -> Pos | V17: Dan | W17: =PROPER(TRIM(V17)) -> Dan | X17: North | Y17: 2 | Z17: =IF(D17="", "Missing", "ok") -> ok | AA17: =(O17*Q17)*(1-R17/100) -> 532.532
A18: T100018 | B18: 2026-02-22 | C18: C3714 | E18: =PROPER(TRIM(D18)) | F18: Female | G18: 8 | H18: =IF(AND(G18>18, G18<65), "Valid", "Invalid") -> Invalid | I18: Kano | J18: =PROPER(TRIM(I18)) -> Kano | K18: groceris | L18: =PROPER(TRIM(K18)) -> Groceris | M18: Rice | N18: =PROPER(TRIM(M18)) -> Rice | O18: 487.9 | P18: 6 | Q18: =IF(P18<1, 1, P18) -> 6 | R18: -10 | S18: =IF(OR(R18<0,R18>100),"invalid","Valid") -> invalid | T18: Transfer | U18: =PROPER(TRIM(T18)) -> Transfer | V18: Ada | W18: =PROPER(TRIM(V18)) -> Ada | X18: South | Y18: 2 | Z18: =IF(D18="", "Missing", "ok") -> Missing | AA18: =(O18*Q18)*(1-R18/100) -> 3220.14
A19: T100019 | B19: 2025-07-11 | C19: C4372 | D19: Peter | E19: =PROPER(TRIM(D19)) -> Peter | F19: Female | G19: 43 | H19: =IF(AND(G19>18, G19<65), "Valid", "Invalid") -> Valid | I19: Abuja | J19: =PROPER(TRIM(I19)) -> Abuja | K19: Sports | L19: =PROPER(TRIM(K19)) -> Sports | M19: Ball | N19: =PROPER(TRIM(M19)) -> Ball | O19: 398.62 | P19: -2 | Q19: =IF(P19<1, 1, P19) -> 1 | R19: 10 | S19: =IF(OR(R19<0,R19>100),"invalid","Valid") -> Valid | U19: =PROPER(TRIM(T19)) | V19: Ben | W19: =PROPER(TRIM(V19)) -> Ben | X19: West | Y19: 1 | Z19: =IF(D19="", "Missing", "ok") -> ok | AA19: =(O19*Q19)*(1-R19/100) -> 358.758
A20: T100020 | B20: 2026-02-25 | C20: C1826 | D20: Mary | E20: =PROPER(TRIM(D20)) -> Mary | F20: Male | G20: 130 | H20: =IF(AND(G20>18, G20<65), "Valid", "Invalid") -> Invalid | I20: Kano | J20: =PROPER(TRIM(I20)) -> Kano | K20: groceris | L20: =PROPER(TRIM(K20)) -> Groceris | M20: Rice | N20: =PROPER(TRIM(M20)) -> Rice | O20: 68.67 | P20: 4 | Q20: =IF(P20<1, 1, P20) -> 4 | R20: 10 | S20: =IF(OR(R20<0,R20>100),"invalid","Valid") -> Valid | U20: =PROPER(TRIM(T20)) | V20: Ben | W20: =PROPER(TRIM(V20)) -> Ben | X20: West | Z20: =IF(D20="", "Missing", "ok") -> ok | AA20: =(O20*Q20)*(1-R20/100) -> 247.212
A21: T100021 | B21: 02/07/2025 | C21: C8532 | D21: John | E21: =PROPER(TRIM(D21)) -> John | F21: Male | G21: 8 | H21: =IF(AND(G21>18, G21<65), "Valid", "Invalid") -> Invalid | I21: Abuja | J21: =PROPER(TRIM(I21)) -> Abuja | K21: Fashion | L21: =PROPER(TRIM(K21)) -> Fashion | M21: Shirt | N21: =PROPER(TRIM(M21)) -> Shirt | O21: 477.46 | P21: -2 | Q21: =IF(P21<1, 1, P21) -> 1 | R21: -10 | S21: =IF(OR(R21<0,R21>100),"invalid","Valid") -> invalid | T21: Cash | U21: =PROPER(TRIM(T21)) -> Cash | V21: Ada | W21: =PROPER(TRIM(V21)) -> Ada | X21: West | Y21: 2 | Z21: =IF(D21="", "Missing", "ok") -> ok | AA21: =(O21*Q21)*(1-R21/100) -> 525.206
A22: T100022 | B22: 2025-10-19 | C22: C1462 | D22: David | E22: =PROPER(TRIM(D22)) -> David | F22: Male | G22: 130 | H22: =IF(AND(G22>18, G22<65), "Valid", "Invalid") -> Invalid | I22: Enugu | J22: =PROPER(TRIM(I22)) -> Enugu | K22: Sports | L22: =PROPER(TRIM(K22)) -> Sports | M22: Ball | N22: =PROPER(TRIM(M22)) -> Ball | O22: 29.5 | P22: -2 | Q22: =IF(P22<1, 1, P22) -> 1 | R22: 120 | S22: =IF(OR(R22<0,R22>100),"invalid","Valid") -> invalid | T22: Cash | U22: =PROPER(TRIM(T22)) -> Cash | V22: Dan | W22: =PROPER(TRIM(V22)) -> Dan | X22: South | Y22: 3 | Z22: =IF(D22="", "Missing", "ok") -> ok | AA22: =(O22*Q22)*(1-R22/100) -> -5.9
A23: T100023 | B23: 2025-08-16 | C23: C6481 | D23: James | E23: =PROPER(TRIM(D23)) -> James | F23: Male | G23: 8 | H23: =IF(AND(G23>18, G23<65), "Valid", "Invalid") -> Invalid | I23: lagos | J23: =PROPER(TRIM(I23)) -> Lagos | K23: Beauty | L23: =PROPER(TRIM(K23)) -> Beauty | M23: Cream | N23: =PROPER(TRIM(M23)) -> Cream | O23: 134.08 | P23: 5 | Q23: =IF(P23<1, 1, P23) -> 5 | R23: 0 | S23: =IF(OR(R23<0,R23>100),"invalid","Valid") -> Valid | U23: =PROPER(TRIM(T23)) | V23: Ben | W23: =PROPER(TRIM(V23)) -> Ben | X23: South | Y23: 2 | Z23: =IF(D23="", "Missing", "ok") -> ok | AA23: =(O23*Q23)*(1-R23/100) -> 670.4
A24: T100024 | B24: 2025-09-24 | C24: C2962 | D24: Grace | E24: =PROPER(TRIM(D24)) -> Grace | F24: Female | G24: 130 | H24: =IF(AND(G24>18, G24<65), "Valid", "Invalid") -> Invalid | I24: Abuja | J24: =PROPER(TRIM(I24)) -> Abuja | K24: Fashion | L24: =PROPER(TRIM(K24)) -> Fashion | M24: Shirt | N24: =PROPER(TRIM(M24)) -> Shirt | O24: 388.4 | P24: -2 | Q24: =IF(P24<1, 1, P24) -> 1 | R24: 15 | S24: =IF(OR(R24<0,R24>100),"invalid","Valid") -> Valid | T24: Mobile Money | U24: =PROPER(TRIM(T24)) -> Mobile Money | V24: Ada | W24: =PROPER(TRIM(V24)) -> Ada | X24: North | Y24: 1 | Z24: =IF(D24="", "Missing", "ok") -> ok | AA24: =(O24*Q24)*(1-R24/100) -> 330.14
A25: T100025 | B25: 2025-06-10 | C25: C3575 | D25: James | E25: =PROPER(TRIM(D25)) -> James | F25: Female | G25: 130 | H25: =IF(AND(G25>18, G25<65), "Valid", "Invalid") -> Invalid | I25: Kano | J25: =PROPER(TRIM(I25)) -> Kano | K25: Fashion | L25: =PROPER(TRIM(K25)) -> Fashion | M25: Shirt | N25: =PROPER(TRIM(M25)) -> Shirt | O25: 279.11 | P25: -2 | Q25: =IF(P25<1, 1, P25) -> 1 | R25: 10 | S25: =IF(OR(R25<0,R25>100),"invalid","Valid") -> Valid | T25: Transfer | U25: =PROPER(TRIM(T25)) -> Transfer | V25: Ben | W25: =PROPER(TRIM(V25)) -> Ben | X25: West | Z25: =IF(D25="", "Missing", "ok") -> ok | AA25: =(O25*Q25)*(1-R25/100) -> 251.199
A26: T100026 | B26: 2025-05-26 | C26: C5211 | D26: David | E26: =PROPER(TRIM(D26)) -> David | F26: Male | G26: 130 | H26: =IF(AND(G26>18, G26<65), "Valid", "Invalid") -> Invalid | I26: Abuja | J26: =PROPER(TRIM(I26)) -> Abuja | K26: Beauty | L26: =PROPER(TRIM(K26)) -> Beauty | M26: Cream | N26: =PROPER(TRIM(M26)) -> Cream | O26: 205.37 | P26: -2 | Q26: =IF(P26<1, 1, P26) -> 1 | R26: -10 | S26: =IF(OR(R26<0,R26>100),"invalid","Valid") -> invalid | T26: Cash | U26: =PROPER(TRIM(T26)) -> Cash | V26: Ada | W26: =PROPER(TRIM(V26)) -> Ada | X26: North | Z26: =IF(D26="", "Missing", "ok") -> ok | AA26: =(O26*Q26)*(1-R26/100) -> 225.907
A27: T100027 | B27: 2025-05-27 | C27: C5215 | D27: Aisha | E27: =PROPER(TRIM(D27)) -> Aisha | F27: Female | G27: 58 | H27: =IF(AND(G27>18, G27<65), "Valid", "Invalid") -> Valid | I27: PH | J27: =PROPER(TRIM(I27)) -> Ph | K27: groceris | L27: =PROPER(TRIM(K27)) -> Groceris | M27: Rice | N27: =PROPER(TRIM(M27)) -> Rice | O27: 72.55 | P27: 6 | Q27: =IF(P27<1, 1, P27) -> 6 | R27: 15 | S27: =IF(OR(R27<0,R27>100),"invalid","Valid") -> Valid | T27: Mobile Money | U27: =PROPER(TRIM(T27)) -> Mobile Money | V27: Ben | W27: =PROPER(TRIM(V27)) -> Ben | X27: East | Y27: 1 | Z27: =IF(D27="", "Missing", "ok") -> ok | AA27: =(O27*Q27)*(1-R27/100) -> 370.005
A28: T100028 | B28: 07/01/2025 | C28: C8821 | D28: Mary | E28: =PROPER(TRIM(D28)) -> Mary | F28: Female | G28: 130 | H28: =IF(AND(G28>18, G28<65), "Valid", "Invalid") -> Invalid | I28: lagos | J28: =PROPER(TRIM(I28)) -> Lagos | K28: groceris | L28: =PROPER(TRIM(K28)) -> Groceris | M28: Rice | N28: =PROPER(TRIM(M28)) -> Rice | O28: 275.95 | P28: -2 | Q28: =IF(P28<1, 1, P28) -> 1 | R28: 10 | S28: =IF(OR(R28<0,R28>100),"invalid","Valid") -> Valid | U28: =PROPER(TRIM(T28)) | V28: Dan | W28: =PROPER(TRIM(V28)) -> Dan | X28: West | Y28: 3 | Z28: =IF(D28="", "Missing", "ok") -> ok | AA28: =(O28*Q28)*(1-R28/100) -> 248.355
A29: T100029 | B29: 2025-10-19 | C29: C2182 | D29: Aisha | E29: =PROPER(TRIM(D29)) -> Aisha | F29: Female | G29: 8 | H29: =IF(AND(G29>18, G29<65), "Valid", "Invalid") -> Invalid | I29: Enugu | J29: =PROPER(TRIM(I29)) -> Enugu | K29: Beauty | L29: =PROPER(TRIM(K29)) -> Beauty | M29: Cream | N29: =PROPER(TRIM(M29)) -> Cream | O29: 161.33 | P29: 4 | Q29: =IF(P29<1, 1, P29) -> 4 | R29: 10 | S29: =IF(OR(R29<0,R29>100),"invalid","Valid") -> Valid | T29: Cash | U29: =PROPER(TRIM(T29)) -> Cash | V29: Ben | W29: =PROPER(TRIM(V29)) -> Ben | X29: East | Y29: 3 | Z29: =IF(D29="", "Missing", "ok") -> ok | AA29: =(O29*Q29)*(1-R29/100) -> 580.788
A30: T100030 | B30: 2026-01-06 | C30: C5052 | E30: =PROPER(TRIM(D30)) | F30: Female | G30: 58 | H30: =IF(AND(G30>18, G30<65), "Valid", "Invalid") -> Valid | I30: Lagos | J30: =PROPER(TRIM(I30)) -> Lagos | K30: Beauty | L30: =PROPER(TRIM(K30)) -> Beauty | M30: Cream | N30: =PROPER(TRIM(M30)) -> Cream | O30: 416.14 | P30: 10 | Q30: =IF(P30<1, 1, P30) -> 10 | R30: 120 | S30: =IF(OR(R30<0,R30>100),"invalid","Valid") -> invalid | T30: Mobile Money | U30: =PROPER(TRIM(T30)) -> Mobile Money | V30: Ada | W30: =PROPER(TRIM(V30)) -> Ada | X30: North | Y30: 1 | Z30: =IF(D30="", "Missing", "ok") -> Missing | AA30: =(O30*Q30)*(1-R30/100) -> -832.28
A31: T100031 | B31: 2026-02-16 | C31: C6457 | D31: John | E31: =PROPER(TRIM(D31)) -> John | F31: Male | G31: 8 | H31: =IF(AND(G31>18, G31<65), "Valid", "Invalid") -> Invalid | I31: PH | J31: =PROPER(TRIM(I31)) -> Ph | K31: groceris | L31: =PROPER(TRIM(K31)) -> Groceris | M31: Rice | N31: =PROPER(TRIM(M31)) -> Rice | O31: 258.57 | P31: 2 | Q31: =IF(P31<1, 1, P31) -> 2 | R31: -10 | S31: =IF(OR(R31<0,R31>100),"invalid","Valid") -> invalid | T31: POS | U31: =PROPER(TRIM(T31)) -> Pos | V31: Ben | W31: =PROPER(TRIM(V31)) -> Ben | X31: West | Y31: 3 | Z31: =IF(D31="", "Missing", "ok") -> ok | AA31: =(O31*Q31)*(1-R31/100) -> 568.854
A32: T100032 | B32: 2025-03-23 | C32: C8802 | D32: John | E32: =PROPER(TRIM(D32)) -> John | F32: Male | G32: 130 | H32: =IF(AND(G32>18, G32<65), "Valid", "Invalid") -> Invalid | I32: LAGOS | J32: =PROPER(TRIM(I32)) -> Lagos | K32: Sports | L32: =PROPER(TRIM(K32)) -> Sports | M32: Ball | N32: =PROPER(TRIM(M32)) -> Ball | O32: 395.37 | P32: -2 | Q32: =IF(P32<1, 1, P32) -> 1 | R32: 5 | S32: =IF(OR(R32<0,R32>100),"invalid","Valid") -> Valid | T32: Mobile Money | U32: =PROPER(TRIM(T32)) -> Mobile Money | V32: Ada | W32: =PROPER(TRIM(V32)) -> Ada | X32: South | Y32: 4 | Z32: =IF(D32="", "Missing", "ok") -> ok | AA32: =(O32*Q32)*(1-R32/100) -> 375.6015
A33: T100033 | B33: 2025-10-09 | C33: C7652 | D33: Aisha | E33: =PROPER(TRIM(D33)) -> Aisha | F33: Male | G33: 37 | H33: =IF(AND(G33>18, G33<65), "Valid", "Invalid") -> Valid | I33: Kano | J33: =PROPER(TRIM(I33)) -> Kano | K33: Sports | L33: =PROPER(TRIM(K33)) -> Sports | M33: Ball | N33: =PROPER(TRIM(M33)) -> Ball | O33: 429.08 | P33: 9 | Q33: =IF(P33<1, 1, P33) -> 9 | R33: 0 | S33: =IF(OR(R33<0,R33>100),"invalid","Valid") -> Valid | T33: Mobile Money | U33: =PROPER(TRIM(T33)) -> Mobile Money | V33: Chi | W33: =PROPER(TRIM(V33)) -> Chi | X33: East | Y33: 4 | Z33: =IF(D33="", "Missing", "ok") -> ok | AA33: =(O33*Q33)*(1-R33/100) -> 3861.72
A34: T100034 | B34: 2025-07-11 | C34: C9293 | D34: David | E34: =PROPER(TRIM(D34)) -> David | F34: Female | G34: 35 | H34: =IF(AND(G34>18, G34<65), "Valid", "Invalid") -> Valid | I34: Enugu | J34: =PROPER(TRIM(I34)) -> Enugu | K34: groceris | L34: =PROPER(TRIM(K34)) -> Groceris | M34: Rice | N34: =PROPER(TRIM(M34)) -> Rice | O34: 467.61 | P34: -2 | Q34: =IF(P34<1, 1, P34) -> 1 | R34: 120 | S34: =IF(OR(R34<0,R34>100),"invalid","Valid") -> invalid | T34: Transfer | U34: =PROPER(TRIM(T34)) -> Transfer | V34: Chi | W34: =PROPER(TRIM(V34)) -> Chi | X34: East | Y34: 4 | Z34: =IF(D34="", "Missing", "ok") -> ok | AA34: =(O34*Q34)*(1-R34/100) -> -93.522
A35: T100035 | B35: 13/03/2026 | C35: C2683 | D35: Mary | E35: =PROPER(TRIM(D35)) -> Mary | F35: Female | G35: 130 | H35: =IF(AND(G35>18, G35<65), "Valid", "Invalid") -> Invalid | I35: PH | J35: =PROPER(TRIM(I35)) -> Ph | K35: Beauty | L35: =PROPER(TRIM(K35)) -> Beauty | M35: Cream | N35: =PROPER(TRIM(M35)) -> Cream | O35: 402.37 | P35: 10 | Q35: =IF(P35<1, 1, P35) -> 10 | R35: 0 | S35: =IF(OR(R35<0,R35>100),"invalid","Valid") -> Valid | T35: Transfer | U35: =PROPER(TRIM(T35)) -> Transfer | V35: Dan | W35: =PROPER(TRIM(V35)) -> Dan | X35: South | Y35: 4 | Z35: =IF(D35="", "Missing", "ok") -> ok | AA35: =(O35*Q35)*(1-R35/100) -> 4023.7
A36: T100036 | B36: 2025-12-30 | C36: C1794 | D36: Grace | E36: =PROPER(TRIM(D36)) -> Grace | F36: Male | G36: 19 | H36: =IF(AND(G36>18, G36<65), "Valid", "Invalid") -> Valid | I36: LAGOS | J36: =PROPER(TRIM(I36)) -> Lagos | K36: Home | L36: =PROPER(TRIM(K36)) -> Home | M36: Chair | N36: =PROPER(TRIM(M36)) -> Chair | O36: 489.41 | P36: 1 | Q36: =IF(P36<1, 1, P36) -> 1 | R36: 0 | S36: =IF(OR(R36<0,R36>100),"invalid","Valid") -> Valid | T36: Transfer | U36: =PROPER(TRIM(T36)) -> Transfer | V36: Chi | W36: =PROPER(TRIM(V36)) -> Chi | X36: South | Y36: 3 | Z36: =IF(D36="", "Missing", "ok") -> ok | AA36: =(O36*Q36)*(1-R36/100) -> 489.41
A37: T100037 | B37: 2025-11-16 | C37: C3074 | D37: John | E37: =PROPER(TRIM(D37)) -> John | F37: Female | G37: 64 | H37: =IF(AND(G37>18, G37<65), "Valid", "Invalid") -> Valid | I37: LAGOS | J37: =PROPER(TRIM(I37)) -> Lagos | K37: Fashion | L37: =PROPER(TRIM(K37)) -> Fashion | M37: Shirt | N37: =PROPER(TRIM(M37)) -> Shirt | O37: 203.77 | P37: 9 | Q37: =IF(P37<1, 1, P37) -> 9 | R37: 120 | S37: =IF(OR(R37<0,R37>100),"invalid","Valid") -> invalid | T37: Transfer | U37: =PROPER(TRIM(T37)) -> Transfer | V37: Chi | W37: =PROPER(TRIM(V37)) -> Chi | X37: South | Y37: 3 | Z37: =IF(D37="", "Missing", "ok") -> ok | AA37: =(O37*Q37)*(1-R37/100) -> -366.786
A38: T100038 | B38: 2025-07-10 | C38: C2121 | D38: James | E38: =PROPER(TRIM(D38)) -> James | F38: Female | G38: 8 | H38: =IF(AND(G38>18, G38<65), "Valid", "Invalid") -> Invalid | I38: PH | J38: =PROPER(TRIM(I38)) -> Ph | K38: Sports | L38: =PROPER(TRIM(K38)) -> Sports | M38: Ball | N38: =PROPER(TRIM(M38)) -> Ball | O38: 333.17 | P38: 8 | Q38: =IF(P38<1, 1, P38) -> 8 | R38: -10 | S38: =IF(OR(R38<0,R38>100),"invalid","Valid") -> invalid | T38: Cash | U38: =PROPER(TRIM(T38)) -> Cash | V38: Ada | W38: =PROPER(TRIM(V38)) -> Ada | X38: South | Y38: 4 | Z38: =IF(D38="", "Missing", "ok") -> ok | AA38: =(O38*Q38)*(1-R38/100) -> 2931.896
A39: T100039 | B39: 2025-12-11 | C39: C5675 | D39: John | E39: =PROPER(TRIM(D39)) -> John | F39: Female | G39: 130 | H39: =IF(AND(G39>18, G39<65), "Valid", "Invalid") -> Invalid | I39: Kano | J39: =PROPER(TRIM(I39)) -> Kano | K39: Home | L39: =PROPER(TRIM(K39)) -> Home | M39: Chair | N39: =PROPER(TRIM(M39)) -> Chair | O39: 166.86 | P39: -2 | Q39: =IF(P39<1, 1, P39) -> 1 | R39: 5 | S39: =IF(OR(R39<0,R39>100),"invalid","Valid") -> Valid | T39: Mobile Money | U39: =PROPER(TRIM(T39)) -> Mobile Money | V39: Chi | W39: =PROPER(TRIM(V39)) -> Chi | X39: South | Y39: 3 | Z39: =IF(D39="", "Missing", "ok") -> ok | AA39: =(O39*Q39)*(1-R39/100) -> 158.517
A40: T100040 | B40: 2025-01-28 | C40: C5040 | D40: John | E40: =PROPER(TRIM(D40)) -> John | F40: Female | G40: 19 | H40: =IF(AND(G40>18, G40<65), "Valid", "Invalid") -> Valid | I40: Kano | J40: =PROPER(TRIM(I40)) -> Kano | K40: Beauty | L40: =PROPER(TRIM(K40)) -> Beauty | M40: Cream | N40: =PROPER(TRIM(M40)) -> Cream | O40: 442.23 | P40: -2 | Q40: =IF(P40<1, 1, P40) -> 1 | R40: 120 | S40: =IF(OR(R40<0,R40>100),"invalid","Valid") -> invalid | T40: POS | U40: =PROPER(TRIM(T40)) -> Pos | V40: Chi | W40: =PROPER(TRIM(V40)) -> Chi | X40: South | Y40: 1 | Z40: =IF(D40="", "Missing", "ok") -> ok | AA40: =(O40*Q40)*(1-R40/100) -> -88.446
...

Sheet EDA
A1: KPI | B1: Value
A2: Total_Revenue | B2: =SUM('WORKING DATA'!Q:Q) -> 3944
A3: Number_of_Transactions | B3: =COUNTA('WORKING DATA'!A:A)-1 -> 1196
A4: Ave._Transaction | B4: =AVERAGE('WORKING DATA'!Q:Q) -> 3.2976589
A5: Highest_Sale | B5: =MAX('WORKING DATA'!Q:Q) -> 42
A6: Lowest_Sale | B6: =MIN('WORKING DATA'!Q:Q) -> 1
A9: Product_Category | B9: Revenue
A10: Electronic | B10: =SUMIF('WORKING DATA'!K:K,A10,'WORKING DATA'!AA:AA) -> 0
A11: Groceries | B11: =SUMIF('WORKING DATA'!K:K,A11,'WORKING DATA'!AA:AA) -> 88690.391
A12: Fashion | B12: =SUMIF('WORKING DATA'!K:K,A12,'WORKING DATA'!AA:AA) -> 118710.26
A13: Home | B13: =SUMIF('WORKING DATA'!K:K,A13,'WORKING DATA'!AA:AA) -> 83554.633
A14: Beauty | B14: =SUMIF('WORKING DATA'!K:K,A14,'WORKING DATA'!AA:AA) -> 109063.33
A15: Sports | B15: =SUMIF('WORKING DATA'!K:K,A15,'WORKING DATA'!AA:AA) -> 112686.8
A18: Branch | B18: Revenue
A19: North | B19: =SUMIF('WORKING DATA'!X:X,A18,'WORKING DATA'!AA:AA) -> 0
A20: South | B20: =SUMIF('WORKING DATA'!X:X,A19,'WORKING DATA'!AA:AA) -> 209640.86
A21: West | B21: =SUMIF('WORKING DATA'!X:X,A20,'WORKING DATA'!AA:AA) -> 168416.76
A22: East | B22: =SUMIF('WORKING DATA'!X:X,A21,'WORKING DATA'!AA:AA) -> 195085.64
A25: City | B25: Revenue
A26: Lagos | B26: =SUMIF('WORKING DATA'!I:I, A26, 'WORKING DATA'!AA:AA) -> 308160.4
A27: Abuja | B27: =SUMIF('WORKING DATA'!I:I, A27, 'WORKING DATA'!AA:AA) -> 138012.53
A28: Kano | B28: =SUMIF('WORKING DATA'!I:I, A28, 'WORKING DATA'!AA:AA) -> 107389.43
A29: Enugu | B29: =SUMIF('WORKING DATA'!I:I, A29, 'WORKING DATA'!AA:AA) -> 107638.82
A30: Ph | B30: =SUMIF('WORKING DATA'!I:I, A30, 'WORKING DATA'!AA:AA) -> 104867.74
